/tmp/slurmd/job51426425/slurm_script: line 0: unalias: pine: not found
/tmp/slurmd/job51426425/slurm_script: line 0: unalias: quota: not found
/tmp/slurmd/job51426425/slurm_script: line 0: unalias: chsh: not found
/tmp/slurmd/job51426425/slurm_script: line 0: unalias: grpe: not found
/tmp/slurmd/job51426425/slurm_script: line 0: unalias: alloc: not found
/tmp/slurmd/job51426425/slurm_script: line 0: unalias: vi: not found
/tmp/slurmd/job51426425/slurm_script: line 0: unalias: chfn: not found
WARNING: Anaconda2/5.1.0 cannot be loaded due to a conflict.
HINT: Might try "module unload Anaconda3" first.
Traceback (most recent call last):
  File "/home/casperneo/.local/lib/python3.6/site-packages/tensorflow/python/pywrap_tensorflow.py", line 58, in <module>
    from tensorflow.python.pywrap_tensorflow_internal import *
  File "/home/casperneo/.local/lib/python3.6/site-packages/tensorflow/python/pywrap_tensorflow_internal.py", line 28, in <module>
    _pywrap_tensorflow_internal = swig_import_helper()
  File "/home/casperneo/.local/lib/python3.6/site-packages/tensorflow/python/pywrap_tensorflow_internal.py", line 24, in swig_import_helper
    _mod = imp.load_module('_pywrap_tensorflow_internal', fp, pathname, description)
  File "/software/Anaconda3-4.3.0-el7-x86_64/lib/python3.6/imp.py", line 243, in load_module
    return load_dynamic(name, filename, file)
  File "/software/Anaconda3-4.3.0-el7-x86_64/lib/python3.6/imp.py", line 343, in load_dynamic
    return _load(spec)
ImportError: libcublas.so.9.0: cannot open shared object file: No such file or directory

During handling of the above exception, another exception occurred:

Traceback (most recent call last):
  File "reproduction/pipeline/into_record.py", line 1, in <module>
    import tensorflow as tf
  File "/home/casperneo/.local/lib/python3.6/site-packages/tensorflow/__init__.py", line 22, in <module>
    from tensorflow.python import pywrap_tensorflow  # pylint: disable=unused-import
  File "/home/casperneo/.local/lib/python3.6/site-packages/tensorflow/python/__init__.py", line 49, in <module>
    from tensorflow.python import pywrap_tensorflow
  File "/home/casperneo/.local/lib/python3.6/site-packages/tensorflow/python/pywrap_tensorflow.py", line 74, in <module>
    raise ImportError(msg)
ImportError: Traceback (most recent call last):
  File "/home/casperneo/.local/lib/python3.6/site-packages/tensorflow/python/pywrap_tensorflow.py", line 58, in <module>
    from tensorflow.python.pywrap_tensorflow_internal import *
  File "/home/casperneo/.local/lib/python3.6/site-packages/tensorflow/python/pywrap_tensorflow_internal.py", line 28, in <module>
    _pywrap_tensorflow_internal = swig_import_helper()
  File "/home/casperneo/.local/lib/python3.6/site-packages/tensorflow/python/pywrap_tensorflow_internal.py", line 24, in swig_import_helper
    _mod = imp.load_module('_pywrap_tensorflow_internal', fp, pathname, description)
  File "/software/Anaconda3-4.3.0-el7-x86_64/lib/python3.6/imp.py", line 243, in load_module
    return load_dynamic(name, filename, file)
  File "/software/Anaconda3-4.3.0-el7-x86_64/lib/python3.6/imp.py", line 343, in load_dynamic
    return _load(spec)
ImportError: libcublas.so.9.0: cannot open shared object file: No such file or directory


Failed to load the native TensorFlow runtime.

See https://www.tensorflow.org/install/install_sources#common_installation_problems

for some common reasons and solutions.  Include the entire stack trace
above this error message when asking for help.
Traceback (most recent call last):
  File "/home/casperneo/.local/lib/python3.6/site-packages/tensorflow/python/pywrap_tensorflow.py", line 58, in <module>
    from tensorflow.python.pywrap_tensorflow_internal import *
  File "/home/casperneo/.local/lib/python3.6/site-packages/tensorflow/python/pywrap_tensorflow_internal.py", line 28, in <module>
    _pywrap_tensorflow_internal = swig_import_helper()
  File "/home/casperneo/.local/lib/python3.6/site-packages/tensorflow/python/pywrap_tensorflow_internal.py", line 24, in swig_import_helper
    _mod = imp.load_module('_pywrap_tensorflow_internal', fp, pathname, description)
  File "/software/Anaconda3-4.3.0-el7-x86_64/lib/python3.6/imp.py", line 243, in load_module
    return load_dynamic(name, filename, file)
  File "/software/Anaconda3-4.3.0-el7-x86_64/lib/python3.6/imp.py", line 343, in load_dynamic
    return _load(spec)
ImportError: libcublas.so.9.0: cannot open shared object file: No such file or directory

During handling of the above exception, another exception occurred:

Traceback (most recent call last):
  File "reproduction/pipeline/into_record.py", line 1, in <module>
    import tensorflow as tf
  File "/home/casperneo/.local/lib/python3.6/site-packages/tensorflow/__init__.py", line 22, in <module>
    from tensorflow.python import pywrap_tensorflow  # pylint: disable=unused-import
  File "/home/casperneo/.local/lib/python3.6/site-packages/tensorflow/python/__init__.py", line 49, in <module>
    from tensorflow.python import pywrap_tensorflow
  File "/home/casperneo/.local/lib/python3.6/site-packages/tensorflow/python/pywrap_tensorflow.py", line 74, in <module>
    raise ImportError(msg)
ImportError: Traceback (most recent call last):
  File "/home/casperneo/.local/lib/python3.6/site-packages/tensorflow/python/pywrap_tensorflow.py", line 58, in <module>
    from tensorflow.python.pywrap_tensorflow_internal import *
  File "/home/casperneo/.local/lib/python3.6/site-packages/tensorflow/python/pywrap_tensorflow_internal.py", line 28, in <module>
    _pywrap_tensorflow_internal = swig_import_helper()
  File "/home/casperneo/.local/lib/python3.6/site-packages/tensorflow/python/pywrap_tensorflow_internal.py", line 24, in swig_import_helper
    _mod = imp.load_module('_pywrap_tensorflow_internal', fp, pathname, description)
  File "/software/Anaconda3-4.3.0-el7-x86_64/lib/python3.6/imp.py", line 243, in load_module
    return load_dynamic(name, filename, file)
  File "/software/Anaconda3-4.3.0-el7-x86_64/lib/python3.6/imp.py", line 343, in load_dynamic
    return _load(spec)
ImportError: libcublas.so.9.0: cannot open shared object file: No such file or directory


Failed to load the native TensorFlow runtime.

See https://www.tensorflow.org/install/install_sources#common_installation_problems

for some common reasons and solutions.  Include the entire stack trace
above this error message when asking for help.
Traceback (most recent call last):
  File "/home/casperneo/.local/lib/python3.6/site-packages/tensorflow/python/pywrap_tensorflow.py", line 58, in <module>
    from tensorflow.python.pywrap_tensorflow_internal import *
  File "/home/casperneo/.local/lib/python3.6/site-packages/tensorflow/python/pywrap_tensorflow_internal.py", line 28, in <module>
    _pywrap_tensorflow_internal = swig_import_helper()
  File "/home/casperneo/.local/lib/python3.6/site-packages/tensorflow/python/pywrap_tensorflow_internal.py", line 24, in swig_import_helper
    _mod = imp.load_module('_pywrap_tensorflow_internal', fp, pathname, description)
  File "/software/Anaconda3-4.3.0-el7-x86_64/lib/python3.6/imp.py", line 243, in load_module
    return load_dynamic(name, filename, file)
  File "/software/Anaconda3-4.3.0-el7-x86_64/lib/python3.6/imp.py", line 343, in load_dynamic
    return _load(spec)
ImportError: libcublas.so.9.0: cannot open shared object file: No such file or directory

During handling of the above exception, another exception occurred:

Traceback (most recent call last):
  File "reproduction/pipeline/into_record.py", line 1, in <module>
    import tensorflow as tf
  File "/home/casperneo/.local/lib/python3.6/site-packages/tensorflow/__init__.py", line 22, in <module>
    from tensorflow.python import pywrap_tensorflow  # pylint: disable=unused-import
  File "/home/casperneo/.local/lib/python3.6/site-packages/tensorflow/python/__init__.py", line 49, in <module>
    from tensorflow.python import pywrap_tensorflow
  File "/home/casperneo/.local/lib/python3.6/site-packages/tensorflow/python/pywrap_tensorflow.py", line 74, in <module>
    raise ImportError(msg)
ImportError: Traceback (most recent call last):
  File "/home/casperneo/.local/lib/python3.6/site-packages/tensorflow/python/pywrap_tensorflow.py", line 58, in <module>
    from tensorflow.python.pywrap_tensorflow_internal import *
  File "/home/casperneo/.local/lib/python3.6/site-packages/tensorflow/python/pywrap_tensorflow_internal.py", line 28, in <module>
    _pywrap_tensorflow_internal = swig_import_helper()
  File "/home/casperneo/.local/lib/python3.6/site-packages/tensorflow/python/pywrap_tensorflow_internal.py", line 24, in swig_import_helper
    _mod = imp.load_module('_pywrap_tensorflow_internal', fp, pathname, description)
  File "/software/Anaconda3-4.3.0-el7-x86_64/lib/python3.6/imp.py", line 243, in load_module
    return load_dynamic(name, filename, file)
  File "/software/Anaconda3-4.3.0-el7-x86_64/lib/python3.6/imp.py", line 343, in load_dynamic
    return _load(spec)
ImportError: libcublas.so.9.0: cannot open shared object file: No such file or directory


Failed to load the native TensorFlow runtime.

See https://www.tensorflow.org/install/install_sources#common_installation_problems

for some common reasons and solutions.  Include the entire stack trace
above this error message when asking for help.
Traceback (most recent call last):
  File "/home/casperneo/.local/lib/python3.6/site-packages/tensorflow/python/pywrap_tensorflow.py", line 58, in <module>
    from tensorflow.python.pywrap_tensorflow_internal import *
  File "/home/casperneo/.local/lib/python3.6/site-packages/tensorflow/python/pywrap_tensorflow_internal.py", line 28, in <module>
    _pywrap_tensorflow_internal = swig_import_helper()
  File "/home/casperneo/.local/lib/python3.6/site-packages/tensorflow/python/pywrap_tensorflow_internal.py", line 24, in swig_import_helper
    _mod = imp.load_module('_pywrap_tensorflow_internal', fp, pathname, description)
  File "/software/Anaconda3-4.3.0-el7-x86_64/lib/python3.6/imp.py", line 243, in load_module
    return load_dynamic(name, filename, file)
  File "/software/Anaconda3-4.3.0-el7-x86_64/lib/python3.6/imp.py", line 343, in load_dynamic
    return _load(spec)
ImportError: libcublas.so.9.0: cannot open shared object file: No such file or directory

During handling of the above exception, another exception occurred:

Traceback (most recent call last):
  File "reproduction/pipeline/into_record.py", line 1, in <module>
    import tensorflow as tf
  File "/home/casperneo/.local/lib/python3.6/site-packages/tensorflow/__init__.py", line 22, in <module>
    from tensorflow.python import pywrap_tensorflow  # pylint: disable=unused-import
  File "/home/casperneo/.local/lib/python3.6/site-packages/tensorflow/python/__init__.py", line 49, in <module>
    from tensorflow.python import pywrap_tensorflow
  File "/home/casperneo/.local/lib/python3.6/site-packages/tensorflow/python/pywrap_tensorflow.py", line 74, in <module>
    raise ImportError(msg)
ImportError: Traceback (most recent call last):
  File "/home/casperneo/.local/lib/python3.6/site-packages/tensorflow/python/pywrap_tensorflow.py", line 58, in <module>
    from tensorflow.python.pywrap_tensorflow_internal import *
  File "/home/casperneo/.local/lib/python3.6/site-packages/tensorflow/python/pywrap_tensorflow_internal.py", line 28, in <module>
    _pywrap_tensorflow_internal = swig_import_helper()
  File "/home/casperneo/.local/lib/python3.6/site-packages/tensorflow/python/pywrap_tensorflow_internal.py", line 24, in swig_import_helper
    _mod = imp.load_module('_pywrap_tensorflow_internal', fp, pathname, description)
  File "/software/Anaconda3-4.3.0-el7-x86_64/lib/python3.6/imp.py", line 243, in load_module
    return load_dynamic(name, filename, file)
  File "/software/Anaconda3-4.3.0-el7-x86_64/lib/python3.6/imp.py", line 343, in load_dynamic
    return _load(spec)
ImportError: libcublas.so.9.0: cannot open shared object file: No such file or directory


Failed to load the native TensorFlow runtime.

See https://www.tensorflow.org/install/install_sources#common_installation_problems

for some common reasons and solutions.  Include the entire stack trace
above this error message when asking for help.
Traceback (most recent call last):
  File "/home/casperneo/.local/lib/python3.6/site-packages/tensorflow/python/pywrap_tensorflow.py", line 58, in <module>
    from tensorflow.python.pywrap_tensorflow_internal import *
  File "/home/casperneo/.local/lib/python3.6/site-packages/tensorflow/python/pywrap_tensorflow_internal.py", line 28, in <module>
    _pywrap_tensorflow_internal = swig_import_helper()
  File "/home/casperneo/.local/lib/python3.6/site-packages/tensorflow/python/pywrap_tensorflow_internal.py", line 24, in swig_import_helper
    _mod = imp.load_module('_pywrap_tensorflow_internal', fp, pathname, description)
  File "/software/Anaconda3-4.3.0-el7-x86_64/lib/python3.6/imp.py", line 243, in load_module
    return load_dynamic(name, filename, file)
  File "/software/Anaconda3-4.3.0-el7-x86_64/lib/python3.6/imp.py", line 343, in load_dynamic
    return _load(spec)
ImportError: libcublas.so.9.0: cannot open shared object file: No such file or directory

During handling of the above exception, another exception occurred:

Traceback (most recent call last):
  File "reproduction/pipeline/into_record.py", line 1, in <module>
    import tensorflow as tf
  File "/home/casperneo/.local/lib/python3.6/site-packages/tensorflow/__init__.py", line 22, in <module>
    from tensorflow.python import pywrap_tensorflow  # pylint: disable=unused-import
  File "/home/casperneo/.local/lib/python3.6/site-packages/tensorflow/python/__init__.py", line 49, in <module>
    from tensorflow.python import pywrap_tensorflow
  File "/home/casperneo/.local/lib/python3.6/site-packages/tensorflow/python/pywrap_tensorflow.py", line 74, in <module>
    raise ImportError(msg)
ImportError: Traceback (most recent call last):
  File "/home/casperneo/.local/lib/python3.6/site-packages/tensorflow/python/pywrap_tensorflow.py", line 58, in <module>
    from tensorflow.python.pywrap_tensorflow_internal import *
  File "/home/casperneo/.local/lib/python3.6/site-packages/tensorflow/python/pywrap_tensorflow_internal.py", line 28, in <module>
    _pywrap_tensorflow_internal = swig_import_helper()
  File "/home/casperneo/.local/lib/python3.6/site-packages/tensorflow/python/pywrap_tensorflow_internal.py", line 24, in swig_import_helper
    _mod = imp.load_module('_pywrap_tensorflow_internal', fp, pathname, description)
  File "/software/Anaconda3-4.3.0-el7-x86_64/lib/python3.6/imp.py", line 243, in load_module
    return load_dynamic(name, filename, file)
  File "/software/Anaconda3-4.3.0-el7-x86_64/lib/python3.6/imp.py", line 343, in load_dynamic
    return _load(spec)
ImportError: libcublas.so.9.0: cannot open shared object file: No such file or directory


Failed to load the native TensorFlow runtime.

See https://www.tensorflow.org/install/install_sources#common_installation_problems

for some common reasons and solutions.  Include the entire stack trace
above this error message when asking for help.
Traceback (most recent call last):
  File "/home/casperneo/.local/lib/python3.6/site-packages/tensorflow/python/pywrap_tensorflow.py", line 58, in <module>
    from tensorflow.python.pywrap_tensorflow_internal import *
  File "/home/casperneo/.local/lib/python3.6/site-packages/tensorflow/python/pywrap_tensorflow_internal.py", line 28, in <module>
    _pywrap_tensorflow_internal = swig_import_helper()
  File "/home/casperneo/.local/lib/python3.6/site-packages/tensorflow/python/pywrap_tensorflow_internal.py", line 24, in swig_import_helper
    _mod = imp.load_module('_pywrap_tensorflow_internal', fp, pathname, description)
  File "/software/Anaconda3-4.3.0-el7-x86_64/lib/python3.6/imp.py", line 243, in load_module
    return load_dynamic(name, filename, file)
  File "/software/Anaconda3-4.3.0-el7-x86_64/lib/python3.6/imp.py", line 343, in load_dynamic
    return _load(spec)
ImportError: libcublas.so.9.0: cannot open shared object file: No such file or directory

During handling of the above exception, another exception occurred:

Traceback (most recent call last):
  File "reproduction/pipeline/into_record.py", line 1, in <module>
    import tensorflow as tf
  File "/home/casperneo/.local/lib/python3.6/site-packages/tensorflow/__init__.py", line 22, in <module>
    from tensorflow.python import pywrap_tensorflow  # pylint: disable=unused-import
  File "/home/casperneo/.local/lib/python3.6/site-packages/tensorflow/python/__init__.py", line 49, in <module>
    from tensorflow.python import pywrap_tensorflow
  File "/home/casperneo/.local/lib/python3.6/site-packages/tensorflow/python/pywrap_tensorflow.py", line 74, in <module>
    raise ImportError(msg)
ImportError: Traceback (most recent call last):
  File "/home/casperneo/.local/lib/python3.6/site-packages/tensorflow/python/pywrap_tensorflow.py", line 58, in <module>
    from tensorflow.python.pywrap_tensorflow_internal import *
  File "/home/casperneo/.local/lib/python3.6/site-packages/tensorflow/python/pywrap_tensorflow_internal.py", line 28, in <module>
    _pywrap_tensorflow_internal = swig_import_helper()
  File "/home/casperneo/.local/lib/python3.6/site-packages/tensorflow/python/pywrap_tensorflow_internal.py", line 24, in swig_import_helper
    _mod = imp.load_module('_pywrap_tensorflow_internal', fp, pathname, description)
  File "/software/Anaconda3-4.3.0-el7-x86_64/lib/python3.6/imp.py", line 243, in load_module
    return load_dynamic(name, filename, file)
  File "/software/Anaconda3-4.3.0-el7-x86_64/lib/python3.6/imp.py", line 343, in load_dynamic
    return _load(spec)
ImportError: libcublas.so.9.0: cannot open shared object file: No such file or directory


Failed to load the native TensorFlow runtime.

See https://www.tensorflow.org/install/install_sources#common_installation_problems

for some common reasons and solutions.  Include the entire stack trace
above this error message when asking for help.
Traceback (most recent call last):
  File "/home/casperneo/.local/lib/python3.6/site-packages/tensorflow/python/pywrap_tensorflow.py", line 58, in <module>
    from tensorflow.python.pywrap_tensorflow_internal import *
  File "/home/casperneo/.local/lib/python3.6/site-packages/tensorflow/python/pywrap_tensorflow_internal.py", line 28, in <module>
    _pywrap_tensorflow_internal = swig_import_helper()
  File "/home/casperneo/.local/lib/python3.6/site-packages/tensorflow/python/pywrap_tensorflow_internal.py", line 24, in swig_import_helper
    _mod = imp.load_module('_pywrap_tensorflow_internal', fp, pathname, description)
  File "/software/Anaconda3-4.3.0-el7-x86_64/lib/python3.6/imp.py", line 243, in load_module
    return load_dynamic(name, filename, file)
  File "/software/Anaconda3-4.3.0-el7-x86_64/lib/python3.6/imp.py", line 343, in load_dynamic
    return _load(spec)
ImportError: libcublas.so.9.0: cannot open shared object file: No such file or directory

During handling of the above exception, another exception occurred:

Traceback (most recent call last):
  File "reproduction/pipeline/into_record.py", line 1, in <module>
    import tensorflow as tf
  File "/home/casperneo/.local/lib/python3.6/site-packages/tensorflow/__init__.py", line 22, in <module>
    from tensorflow.python import pywrap_tensorflow  # pylint: disable=unused-import
  File "/home/casperneo/.local/lib/python3.6/site-packages/tensorflow/python/__init__.py", line 49, in <module>
    from tensorflow.python import pywrap_tensorflow
  File "/home/casperneo/.local/lib/python3.6/site-packages/tensorflow/python/pywrap_tensorflow.py", line 74, in <module>
    raise ImportError(msg)
ImportError: Traceback (most recent call last):
  File "/home/casperneo/.local/lib/python3.6/site-packages/tensorflow/python/pywrap_tensorflow.py", line 58, in <module>
    from tensorflow.python.pywrap_tensorflow_internal import *
  File "/home/casperneo/.local/lib/python3.6/site-packages/tensorflow/python/pywrap_tensorflow_internal.py", line 28, in <module>
    _pywrap_tensorflow_internal = swig_import_helper()
  File "/home/casperneo/.local/lib/python3.6/site-packages/tensorflow/python/pywrap_tensorflow_internal.py", line 24, in swig_import_helper
    _mod = imp.load_module('_pywrap_tensorflow_internal', fp, pathname, description)
  File "/software/Anaconda3-4.3.0-el7-x86_64/lib/python3.6/imp.py", line 243, in load_module
    return load_dynamic(name, filename, file)
  File "/software/Anaconda3-4.3.0-el7-x86_64/lib/python3.6/imp.py", line 343, in load_dynamic
    return _load(spec)
ImportError: libcublas.so.9.0: cannot open shared object file: No such file or directory


Failed to load the native TensorFlow runtime.

See https://www.tensorflow.org/install/install_sources#common_installation_problems

for some common reasons and solutions.  Include the entire stack trace
above this error message when asking for help.
Traceback (most recent call last):
  File "/home/casperneo/.local/lib/python3.6/site-packages/tensorflow/python/pywrap_tensorflow.py", line 58, in <module>
    from tensorflow.python.pywrap_tensorflow_internal import *
  File "/home/casperneo/.local/lib/python3.6/site-packages/tensorflow/python/pywrap_tensorflow_internal.py", line 28, in <module>
    _pywrap_tensorflow_internal = swig_import_helper()
  File "/home/casperneo/.local/lib/python3.6/site-packages/tensorflow/python/pywrap_tensorflow_internal.py", line 24, in swig_import_helper
    _mod = imp.load_module('_pywrap_tensorflow_internal', fp, pathname, description)
  File "/software/Anaconda3-4.3.0-el7-x86_64/lib/python3.6/imp.py", line 243, in load_module
    return load_dynamic(name, filename, file)
  File "/software/Anaconda3-4.3.0-el7-x86_64/lib/python3.6/imp.py", line 343, in load_dynamic
    return _load(spec)
ImportError: libcublas.so.9.0: cannot open shared object file: No such file or directory

During handling of the above exception, another exception occurred:

Traceback (most recent call last):
  File "reproduction/pipeline/into_record.py", line 1, in <module>
    import tensorflow as tf
  File "/home/casperneo/.local/lib/python3.6/site-packages/tensorflow/__init__.py", line 22, in <module>
    from tensorflow.python import pywrap_tensorflow  # pylint: disable=unused-import
  File "/home/casperneo/.local/lib/python3.6/site-packages/tensorflow/python/__init__.py", line 49, in <module>
    from tensorflow.python import pywrap_tensorflow
  File "/home/casperneo/.local/lib/python3.6/site-packages/tensorflow/python/pywrap_tensorflow.py", line 74, in <module>
    raise ImportError(msg)
ImportError: Traceback (most recent call last):
  File "/home/casperneo/.local/lib/python3.6/site-packages/tensorflow/python/pywrap_tensorflow.py", line 58, in <module>
    from tensorflow.python.pywrap_tensorflow_internal import *
  File "/home/casperneo/.local/lib/python3.6/site-packages/tensorflow/python/pywrap_tensorflow_internal.py", line 28, in <module>
    _pywrap_tensorflow_internal = swig_import_helper()
  File "/home/casperneo/.local/lib/python3.6/site-packages/tensorflow/python/pywrap_tensorflow_internal.py", line 24, in swig_import_helper
    _mod = imp.load_module('_pywrap_tensorflow_internal', fp, pathname, description)
  File "/software/Anaconda3-4.3.0-el7-x86_64/lib/python3.6/imp.py", line 243, in load_module
    return load_dynamic(name, filename, file)
  File "/software/Anaconda3-4.3.0-el7-x86_64/lib/python3.6/imp.py", line 343, in load_dynamic
    return _load(spec)
ImportError: libcublas.so.9.0: cannot open shared object file: No such file or directory


Failed to load the native TensorFlow runtime.

See https://www.tensorflow.org/install/install_sources#common_installation_problems

for some common reasons and solutions.  Include the entire stack trace
above this error message when asking for help.
Traceback (most recent call last):
  File "/home/casperneo/.local/lib/python3.6/site-packages/tensorflow/python/pywrap_tensorflow.py", line 58, in <module>
    from tensorflow.python.pywrap_tensorflow_internal import *
  File "/home/casperneo/.local/lib/python3.6/site-packages/tensorflow/python/pywrap_tensorflow_internal.py", line 28, in <module>
    _pywrap_tensorflow_internal = swig_import_helper()
  File "/home/casperneo/.local/lib/python3.6/site-packages/tensorflow/python/pywrap_tensorflow_internal.py", line 24, in swig_import_helper
    _mod = imp.load_module('_pywrap_tensorflow_internal', fp, pathname, description)
  File "/software/Anaconda3-4.3.0-el7-x86_64/lib/python3.6/imp.py", line 243, in load_module
    return load_dynamic(name, filename, file)
  File "/software/Anaconda3-4.3.0-el7-x86_64/lib/python3.6/imp.py", line 343, in load_dynamic
    return _load(spec)
ImportError: libcublas.so.9.0: cannot open shared object file: No such file or directory

During handling of the above exception, another exception occurred:

Traceback (most recent call last):
  File "reproduction/pipeline/into_record.py", line 1, in <module>
    import tensorflow as tf
  File "/home/casperneo/.local/lib/python3.6/site-packages/tensorflow/__init__.py", line 22, in <module>
    from tensorflow.python import pywrap_tensorflow  # pylint: disable=unused-import
  File "/home/casperneo/.local/lib/python3.6/site-packages/tensorflow/python/__init__.py", line 49, in <module>
    from tensorflow.python import pywrap_tensorflow
  File "/home/casperneo/.local/lib/python3.6/site-packages/tensorflow/python/pywrap_tensorflow.py", line 74, in <module>
    raise ImportError(msg)
ImportError: Traceback (most recent call last):
  File "/home/casperneo/.local/lib/python3.6/site-packages/tensorflow/python/pywrap_tensorflow.py", line 58, in <module>
    from tensorflow.python.pywrap_tensorflow_internal import *
  File "/home/casperneo/.local/lib/python3.6/site-packages/tensorflow/python/pywrap_tensorflow_internal.py", line 28, in <module>
    _pywrap_tensorflow_internal = swig_import_helper()
  File "/home/casperneo/.local/lib/python3.6/site-packages/tensorflow/python/pywrap_tensorflow_internal.py", line 24, in swig_import_helper
    _mod = imp.load_module('_pywrap_tensorflow_internal', fp, pathname, description)
  File "/software/Anaconda3-4.3.0-el7-x86_64/lib/python3.6/imp.py", line 243, in load_module
    return load_dynamic(name, filename, file)
  File "/software/Anaconda3-4.3.0-el7-x86_64/lib/python3.6/imp.py", line 343, in load_dynamic
    return _load(spec)
ImportError: libcublas.so.9.0: cannot open shared object file: No such file or directory


Failed to load the native TensorFlow runtime.

See https://www.tensorflow.org/install/install_sources#common_installation_problems

for some common reasons and solutions.  Include the entire stack trace
above this error message when asking for help.
Traceback (most recent call last):
  File "/home/casperneo/.local/lib/python3.6/site-packages/tensorflow/python/pywrap_tensorflow.py", line 58, in <module>
    from tensorflow.python.pywrap_tensorflow_internal import *
  File "/home/casperneo/.local/lib/python3.6/site-packages/tensorflow/python/pywrap_tensorflow_internal.py", line 28, in <module>
    _pywrap_tensorflow_internal = swig_import_helper()
  File "/home/casperneo/.local/lib/python3.6/site-packages/tensorflow/python/pywrap_tensorflow_internal.py", line 24, in swig_import_helper
    _mod = imp.load_module('_pywrap_tensorflow_internal', fp, pathname, description)
  File "/software/Anaconda3-4.3.0-el7-x86_64/lib/python3.6/imp.py", line 243, in load_module
    return load_dynamic(name, filename, file)
  File "/software/Anaconda3-4.3.0-el7-x86_64/lib/python3.6/imp.py", line 343, in load_dynamic
    return _load(spec)
ImportError: libcublas.so.9.0: cannot open shared object file: No such file or directory

During handling of the above exception, another exception occurred:

Traceback (most recent call last):
  File "reproduction/pipeline/into_record.py", line 1, in <module>
    import tensorflow as tf
  File "/home/casperneo/.local/lib/python3.6/site-packages/tensorflow/__init__.py", line 22, in <module>
    from tensorflow.python import pywrap_tensorflow  # pylint: disable=unused-import
  File "/home/casperneo/.local/lib/python3.6/site-packages/tensorflow/python/__init__.py", line 49, in <module>
    from tensorflow.python import pywrap_tensorflow
  File "/home/casperneo/.local/lib/python3.6/site-packages/tensorflow/python/pywrap_tensorflow.py", line 74, in <module>
    raise ImportError(msg)
ImportError: Traceback (most recent call last):
  File "/home/casperneo/.local/lib/python3.6/site-packages/tensorflow/python/pywrap_tensorflow.py", line 58, in <module>
    from tensorflow.python.pywrap_tensorflow_internal import *
  File "/home/casperneo/.local/lib/python3.6/site-packages/tensorflow/python/pywrap_tensorflow_internal.py", line 28, in <module>
    _pywrap_tensorflow_internal = swig_import_helper()
  File "/home/casperneo/.local/lib/python3.6/site-packages/tensorflow/python/pywrap_tensorflow_internal.py", line 24, in swig_import_helper
    _mod = imp.load_module('_pywrap_tensorflow_internal', fp, pathname, description)
  File "/software/Anaconda3-4.3.0-el7-x86_64/lib/python3.6/imp.py", line 243, in load_module
    return load_dynamic(name, filename, file)
  File "/software/Anaconda3-4.3.0-el7-x86_64/lib/python3.6/imp.py", line 343, in load_dynamic
    return _load(spec)
ImportError: libcublas.so.9.0: cannot open shared object file: No such file or directory


Failed to load the native TensorFlow runtime.

See https://www.tensorflow.org/install/install_sources#common_installation_problems

for some common reasons and solutions.  Include the entire stack trace
above this error message when asking for help.
Traceback (most recent call last):
  File "/home/casperneo/.local/lib/python3.6/site-packages/tensorflow/python/pywrap_tensorflow.py", line 58, in <module>
    from tensorflow.python.pywrap_tensorflow_internal import *
  File "/home/casperneo/.local/lib/python3.6/site-packages/tensorflow/python/pywrap_tensorflow_internal.py", line 28, in <module>
    _pywrap_tensorflow_internal = swig_import_helper()
  File "/home/casperneo/.local/lib/python3.6/site-packages/tensorflow/python/pywrap_tensorflow_internal.py", line 24, in swig_import_helper
    _mod = imp.load_module('_pywrap_tensorflow_internal', fp, pathname, description)
  File "/software/Anaconda3-4.3.0-el7-x86_64/lib/python3.6/imp.py", line 243, in load_module
    return load_dynamic(name, filename, file)
  File "/software/Anaconda3-4.3.0-el7-x86_64/lib/python3.6/imp.py", line 343, in load_dynamic
    return _load(spec)
ImportError: libcublas.so.9.0: cannot open shared object file: No such file or directory

During handling of the above exception, another exception occurred:

Traceback (most recent call last):
  File "reproduction/pipeline/into_record.py", line 1, in <module>
    import tensorflow as tf
  File "/home/casperneo/.local/lib/python3.6/site-packages/tensorflow/__init__.py", line 22, in <module>
    from tensorflow.python import pywrap_tensorflow  # pylint: disable=unused-import
  File "/home/casperneo/.local/lib/python3.6/site-packages/tensorflow/python/__init__.py", line 49, in <module>
    from tensorflow.python import pywrap_tensorflow
  File "/home/casperneo/.local/lib/python3.6/site-packages/tensorflow/python/pywrap_tensorflow.py", line 74, in <module>
    raise ImportError(msg)
ImportError: Traceback (most recent call last):
  File "/home/casperneo/.local/lib/python3.6/site-packages/tensorflow/python/pywrap_tensorflow.py", line 58, in <module>
    from tensorflow.python.pywrap_tensorflow_internal import *
  File "/home/casperneo/.local/lib/python3.6/site-packages/tensorflow/python/pywrap_tensorflow_internal.py", line 28, in <module>
    _pywrap_tensorflow_internal = swig_import_helper()
  File "/home/casperneo/.local/lib/python3.6/site-packages/tensorflow/python/pywrap_tensorflow_internal.py", line 24, in swig_import_helper
    _mod = imp.load_module('_pywrap_tensorflow_internal', fp, pathname, description)
  File "/software/Anaconda3-4.3.0-el7-x86_64/lib/python3.6/imp.py", line 243, in load_module
    return load_dynamic(name, filename, file)
  File "/software/Anaconda3-4.3.0-el7-x86_64/lib/python3.6/imp.py", line 343, in load_dynamic
    return _load(spec)
ImportError: libcublas.so.9.0: cannot open shared object file: No such file or directory


Failed to load the native TensorFlow runtime.

See https://www.tensorflow.org/install/install_sources#common_installation_problems

for some common reasons and solutions.  Include the entire stack trace
above this error message when asking for help.
Traceback (most recent call last):
  File "/home/casperneo/.local/lib/python3.6/site-packages/tensorflow/python/pywrap_tensorflow.py", line 58, in <module>
    from tensorflow.python.pywrap_tensorflow_internal import *
  File "/home/casperneo/.local/lib/python3.6/site-packages/tensorflow/python/pywrap_tensorflow_internal.py", line 28, in <module>
    _pywrap_tensorflow_internal = swig_import_helper()
  File "/home/casperneo/.local/lib/python3.6/site-packages/tensorflow/python/pywrap_tensorflow_internal.py", line 24, in swig_import_helper
    _mod = imp.load_module('_pywrap_tensorflow_internal', fp, pathname, description)
  File "/software/Anaconda3-4.3.0-el7-x86_64/lib/python3.6/imp.py", line 243, in load_module
    return load_dynamic(name, filename, file)
  File "/software/Anaconda3-4.3.0-el7-x86_64/lib/python3.6/imp.py", line 343, in load_dynamic
    return _load(spec)
ImportError: libcublas.so.9.0: cannot open shared object file: No such file or directory

During handling of the above exception, another exception occurred:

Traceback (most recent call last):
  File "reproduction/pipeline/into_record.py", line 1, in <module>
    import tensorflow as tf
  File "/home/casperneo/.local/lib/python3.6/site-packages/tensorflow/__init__.py", line 22, in <module>
    from tensorflow.python import pywrap_tensorflow  # pylint: disable=unused-import
  File "/home/casperneo/.local/lib/python3.6/site-packages/tensorflow/python/__init__.py", line 49, in <module>
    from tensorflow.python import pywrap_tensorflow
  File "/home/casperneo/.local/lib/python3.6/site-packages/tensorflow/python/pywrap_tensorflow.py", line 74, in <module>
    raise ImportError(msg)
ImportError: Traceback (most recent call last):
  File "/home/casperneo/.local/lib/python3.6/site-packages/tensorflow/python/pywrap_tensorflow.py", line 58, in <module>
    from tensorflow.python.pywrap_tensorflow_internal import *
  File "/home/casperneo/.local/lib/python3.6/site-packages/tensorflow/python/pywrap_tensorflow_internal.py", line 28, in <module>
    _pywrap_tensorflow_internal = swig_import_helper()
  File "/home/casperneo/.local/lib/python3.6/site-packages/tensorflow/python/pywrap_tensorflow_internal.py", line 24, in swig_import_helper
    _mod = imp.load_module('_pywrap_tensorflow_internal', fp, pathname, description)
  File "/software/Anaconda3-4.3.0-el7-x86_64/lib/python3.6/imp.py", line 243, in load_module
    return load_dynamic(name, filename, file)
  File "/software/Anaconda3-4.3.0-el7-x86_64/lib/python3.6/imp.py", line 343, in load_dynamic
    return _load(spec)
ImportError: libcublas.so.9.0: cannot open shared object file: No such file or directory


Failed to load the native TensorFlow runtime.

See https://www.tensorflow.org/install/install_sources#common_installation_problems

for some common reasons and solutions.  Include the entire stack trace
above this error message when asking for help.
Traceback (most recent call last):
  File "/home/casperneo/.local/lib/python3.6/site-packages/tensorflow/python/pywrap_tensorflow.py", line 58, in <module>
    from tensorflow.python.pywrap_tensorflow_internal import *
  File "/home/casperneo/.local/lib/python3.6/site-packages/tensorflow/python/pywrap_tensorflow_internal.py", line 28, in <module>
    _pywrap_tensorflow_internal = swig_import_helper()
  File "/home/casperneo/.local/lib/python3.6/site-packages/tensorflow/python/pywrap_tensorflow_internal.py", line 24, in swig_import_helper
    _mod = imp.load_module('_pywrap_tensorflow_internal', fp, pathname, description)
  File "/software/Anaconda3-4.3.0-el7-x86_64/lib/python3.6/imp.py", line 243, in load_module
    return load_dynamic(name, filename, file)
  File "/software/Anaconda3-4.3.0-el7-x86_64/lib/python3.6/imp.py", line 343, in load_dynamic
    return _load(spec)
ImportError: libcublas.so.9.0: cannot open shared object file: No such file or directory

During handling of the above exception, another exception occurred:

Traceback (most recent call last):
  File "reproduction/pipeline/into_record.py", line 1, in <module>
    import tensorflow as tf
  File "/home/casperneo/.local/lib/python3.6/site-packages/tensorflow/__init__.py", line 22, in <module>
    from tensorflow.python import pywrap_tensorflow  # pylint: disable=unused-import
  File "/home/casperneo/.local/lib/python3.6/site-packages/tensorflow/python/__init__.py", line 49, in <module>
    from tensorflow.python import pywrap_tensorflow
  File "/home/casperneo/.local/lib/python3.6/site-packages/tensorflow/python/pywrap_tensorflow.py", line 74, in <module>
    raise ImportError(msg)
ImportError: Traceback (most recent call last):
  File "/home/casperneo/.local/lib/python3.6/site-packages/tensorflow/python/pywrap_tensorflow.py", line 58, in <module>
    from tensorflow.python.pywrap_tensorflow_internal import *
  File "/home/casperneo/.local/lib/python3.6/site-packages/tensorflow/python/pywrap_tensorflow_internal.py", line 28, in <module>
    _pywrap_tensorflow_internal = swig_import_helper()
  File "/home/casperneo/.local/lib/python3.6/site-packages/tensorflow/python/pywrap_tensorflow_internal.py", line 24, in swig_import_helper
    _mod = imp.load_module('_pywrap_tensorflow_internal', fp, pathname, description)
  File "/software/Anaconda3-4.3.0-el7-x86_64/lib/python3.6/imp.py", line 243, in load_module
    return load_dynamic(name, filename, file)
  File "/software/Anaconda3-4.3.0-el7-x86_64/lib/python3.6/imp.py", line 343, in load_dynamic
    return _load(spec)
ImportError: libcublas.so.9.0: cannot open shared object file: No such file or directory


Failed to load the native TensorFlow runtime.

See https://www.tensorflow.org/install/install_sources#common_installation_problems

for some common reasons and solutions.  Include the entire stack trace
above this error message when asking for help.
Traceback (most recent call last):
  File "/home/casperneo/.local/lib/python3.6/site-packages/tensorflow/python/pywrap_tensorflow.py", line 58, in <module>
    from tensorflow.python.pywrap_tensorflow_internal import *
  File "/home/casperneo/.local/lib/python3.6/site-packages/tensorflow/python/pywrap_tensorflow_internal.py", line 28, in <module>
    _pywrap_tensorflow_internal = swig_import_helper()
  File "/home/casperneo/.local/lib/python3.6/site-packages/tensorflow/python/pywrap_tensorflow_internal.py", line 24, in swig_import_helper
    _mod = imp.load_module('_pywrap_tensorflow_internal', fp, pathname, description)
  File "/software/Anaconda3-4.3.0-el7-x86_64/lib/python3.6/imp.py", line 243, in load_module
    return load_dynamic(name, filename, file)
  File "/software/Anaconda3-4.3.0-el7-x86_64/lib/python3.6/imp.py", line 343, in load_dynamic
    return _load(spec)
ImportError: libcublas.so.9.0: cannot open shared object file: No such file or directory

During handling of the above exception, another exception occurred:

Traceback (most recent call last):
  File "reproduction/pipeline/into_record.py", line 1, in <module>
    import tensorflow as tf
  File "/home/casperneo/.local/lib/python3.6/site-packages/tensorflow/__init__.py", line 22, in <module>
    from tensorflow.python import pywrap_tensorflow  # pylint: disable=unused-import
  File "/home/casperneo/.local/lib/python3.6/site-packages/tensorflow/python/__init__.py", line 49, in <module>
    from tensorflow.python import pywrap_tensorflow
  File "/home/casperneo/.local/lib/python3.6/site-packages/tensorflow/python/pywrap_tensorflow.py", line 74, in <module>
    raise ImportError(msg)
ImportError: Traceback (most recent call last):
  File "/home/casperneo/.local/lib/python3.6/site-packages/tensorflow/python/pywrap_tensorflow.py", line 58, in <module>
    from tensorflow.python.pywrap_tensorflow_internal import *
  File "/home/casperneo/.local/lib/python3.6/site-packages/tensorflow/python/pywrap_tensorflow_internal.py", line 28, in <module>
    _pywrap_tensorflow_internal = swig_import_helper()
  File "/home/casperneo/.local/lib/python3.6/site-packages/tensorflow/python/pywrap_tensorflow_internal.py", line 24, in swig_import_helper
    _mod = imp.load_module('_pywrap_tensorflow_internal', fp, pathname, description)
  File "/software/Anaconda3-4.3.0-el7-x86_64/lib/python3.6/imp.py", line 243, in load_module
    return load_dynamic(name, filename, file)
  File "/software/Anaconda3-4.3.0-el7-x86_64/lib/python3.6/imp.py", line 343, in load_dynamic
    return _load(spec)
ImportError: libcublas.so.9.0: cannot open shared object file: No such file or directory


Failed to load the native TensorFlow runtime.

See https://www.tensorflow.org/install/install_sources#common_installation_problems

for some common reasons and solutions.  Include the entire stack trace
above this error message when asking for help.
Traceback (most recent call last):
  File "/home/casperneo/.local/lib/python3.6/site-packages/tensorflow/python/pywrap_tensorflow.py", line 58, in <module>
    from tensorflow.python.pywrap_tensorflow_internal import *
  File "/home/casperneo/.local/lib/python3.6/site-packages/tensorflow/python/pywrap_tensorflow_internal.py", line 28, in <module>
    _pywrap_tensorflow_internal = swig_import_helper()
  File "/home/casperneo/.local/lib/python3.6/site-packages/tensorflow/python/pywrap_tensorflow_internal.py", line 24, in swig_import_helper
    _mod = imp.load_module('_pywrap_tensorflow_internal', fp, pathname, description)
  File "/software/Anaconda3-4.3.0-el7-x86_64/lib/python3.6/imp.py", line 243, in load_module
    return load_dynamic(name, filename, file)
  File "/software/Anaconda3-4.3.0-el7-x86_64/lib/python3.6/imp.py", line 343, in load_dynamic
    return _load(spec)
ImportError: libcublas.so.9.0: cannot open shared object file: No such file or directory

During handling of the above exception, another exception occurred:

Traceback (most recent call last):
  File "reproduction/pipeline/into_record.py", line 1, in <module>
    import tensorflow as tf
  File "/home/casperneo/.local/lib/python3.6/site-packages/tensorflow/__init__.py", line 22, in <module>
    from tensorflow.python import pywrap_tensorflow  # pylint: disable=unused-import
  File "/home/casperneo/.local/lib/python3.6/site-packages/tensorflow/python/__init__.py", line 49, in <module>
    from tensorflow.python import pywrap_tensorflow
  File "/home/casperneo/.local/lib/python3.6/site-packages/tensorflow/python/pywrap_tensorflow.py", line 74, in <module>
    raise ImportError(msg)
ImportError: Traceback (most recent call last):
  File "/home/casperneo/.local/lib/python3.6/site-packages/tensorflow/python/pywrap_tensorflow.py", line 58, in <module>
    from tensorflow.python.pywrap_tensorflow_internal import *
  File "/home/casperneo/.local/lib/python3.6/site-packages/tensorflow/python/pywrap_tensorflow_internal.py", line 28, in <module>
    _pywrap_tensorflow_internal = swig_import_helper()
  File "/home/casperneo/.local/lib/python3.6/site-packages/tensorflow/python/pywrap_tensorflow_internal.py", line 24, in swig_import_helper
    _mod = imp.load_module('_pywrap_tensorflow_internal', fp, pathname, description)
  File "/software/Anaconda3-4.3.0-el7-x86_64/lib/python3.6/imp.py", line 243, in load_module
    return load_dynamic(name, filename, file)
  File "/software/Anaconda3-4.3.0-el7-x86_64/lib/python3.6/imp.py", line 343, in load_dynamic
    return _load(spec)
ImportError: libcublas.so.9.0: cannot open shared object file: No such file or directory


Failed to load the native TensorFlow runtime.

See https://www.tensorflow.org/install/install_sources#common_installation_problems

for some common reasons and solutions.  Include the entire stack trace
above this error message when asking for help.
Traceback (most recent call last):
  File "/home/casperneo/.local/lib/python3.6/site-packages/tensorflow/python/pywrap_tensorflow.py", line 58, in <module>
    from tensorflow.python.pywrap_tensorflow_internal import *
  File "/home/casperneo/.local/lib/python3.6/site-packages/tensorflow/python/pywrap_tensorflow_internal.py", line 28, in <module>
    _pywrap_tensorflow_internal = swig_import_helper()
  File "/home/casperneo/.local/lib/python3.6/site-packages/tensorflow/python/pywrap_tensorflow_internal.py", line 24, in swig_import_helper
    _mod = imp.load_module('_pywrap_tensorflow_internal', fp, pathname, description)
  File "/software/Anaconda3-4.3.0-el7-x86_64/lib/python3.6/imp.py", line 243, in load_module
    return load_dynamic(name, filename, file)
  File "/software/Anaconda3-4.3.0-el7-x86_64/lib/python3.6/imp.py", line 343, in load_dynamic
    return _load(spec)
ImportError: libcublas.so.9.0: cannot open shared object file: No such file or directory

During handling of the above exception, another exception occurred:

Traceback (most recent call last):
  File "reproduction/pipeline/into_record.py", line 1, in <module>
    import tensorflow as tf
  File "/home/casperneo/.local/lib/python3.6/site-packages/tensorflow/__init__.py", line 22, in <module>
    from tensorflow.python import pywrap_tensorflow  # pylint: disable=unused-import
  File "/home/casperneo/.local/lib/python3.6/site-packages/tensorflow/python/__init__.py", line 49, in <module>
    from tensorflow.python import pywrap_tensorflow
  File "/home/casperneo/.local/lib/python3.6/site-packages/tensorflow/python/pywrap_tensorflow.py", line 74, in <module>
    raise ImportError(msg)
ImportError: Traceback (most recent call last):
  File "/home/casperneo/.local/lib/python3.6/site-packages/tensorflow/python/pywrap_tensorflow.py", line 58, in <module>
    from tensorflow.python.pywrap_tensorflow_internal import *
  File "/home/casperneo/.local/lib/python3.6/site-packages/tensorflow/python/pywrap_tensorflow_internal.py", line 28, in <module>
    _pywrap_tensorflow_internal = swig_import_helper()
  File "/home/casperneo/.local/lib/python3.6/site-packages/tensorflow/python/pywrap_tensorflow_internal.py", line 24, in swig_import_helper
    _mod = imp.load_module('_pywrap_tensorflow_internal', fp, pathname, description)
  File "/software/Anaconda3-4.3.0-el7-x86_64/lib/python3.6/imp.py", line 243, in load_module
    return load_dynamic(name, filename, file)
  File "/software/Anaconda3-4.3.0-el7-x86_64/lib/python3.6/imp.py", line 343, in load_dynamic
    return _load(spec)
ImportError: libcublas.so.9.0: cannot open shared object file: No such file or directory


Failed to load the native TensorFlow runtime.

See https://www.tensorflow.org/install/install_sources#common_installation_problems

for some common reasons and solutions.  Include the entire stack trace
above this error message when asking for help.
