/tmp/slurmd/job50952304/slurm_script: line 0: unalias: pine: not found
/tmp/slurmd/job50952304/slurm_script: line 0: unalias: quota: not found
/tmp/slurmd/job50952304/slurm_script: line 0: unalias: chsh: not found
/tmp/slurmd/job50952304/slurm_script: line 0: unalias: grpe: not found
/tmp/slurmd/job50952304/slurm_script: line 0: unalias: vi: not found
/tmp/slurmd/job50952304/slurm_script: line 0: unalias: alloc: not found
/tmp/slurmd/job50952304/slurm_script: line 0: unalias: chfn: not found
Traceback (most recent call last):
  File "/home/casperneo/.conda/envs/cc2/lib/python3.5/site-packages/tensorflow/python/pywrap_tensorflow.py", line 58, in <module>
    from tensorflow.python.pywrap_tensorflow_internal import *
  File "/home/casperneo/.conda/envs/cc2/lib/python3.5/site-packages/tensorflow/python/pywrap_tensorflow_internal.py", line 28, in <module>
    _pywrap_tensorflow_internal = swig_import_helper()
  File "/home/casperneo/.conda/envs/cc2/lib/python3.5/site-packages/tensorflow/python/pywrap_tensorflow_internal.py", line 24, in swig_import_helper
    _mod = imp.load_module('_pywrap_tensorflow_internal', fp, pathname, description)
  File "/home/casperneo/.conda/envs/cc2/lib/python3.5/imp.py", line 243, in load_module
    return load_dynamic(name, filename, file)
  File "/home/casperneo/.conda/envs/cc2/lib/python3.5/imp.py", line 343, in load_dynamic
    return _load(spec)
ImportError: /lib64/libc.so.6: version `GLIBC_2.17' not found (required by /home/casperneo/.conda/envs/cc2/lib/python3.5/site-packages/tensorflow/python/_pywrap_tensorflow_internal.so)

During handling of the above exception, another exception occurred:

Traceback (most recent call last):
  File "reproduction/pipeline/into_record.py", line 1, in <module>
    import tensorflow as tf
  File "/home/casperneo/.conda/envs/cc2/lib/python3.5/site-packages/tensorflow/__init__.py", line 22, in <module>
    from tensorflow.python import pywrap_tensorflow  # pylint: disable=unused-import
  File "/home/casperneo/.conda/envs/cc2/lib/python3.5/site-packages/tensorflow/python/__init__.py", line 49, in <module>
    from tensorflow.python import pywrap_tensorflow
  File "/home/casperneo/.conda/envs/cc2/lib/python3.5/site-packages/tensorflow/python/pywrap_tensorflow.py", line 74, in <module>
    raise ImportError(msg)
ImportError: Traceback (most recent call last):
  File "/home/casperneo/.conda/envs/cc2/lib/python3.5/site-packages/tensorflow/python/pywrap_tensorflow.py", line 58, in <module>
    from tensorflow.python.pywrap_tensorflow_internal import *
  File "/home/casperneo/.conda/envs/cc2/lib/python3.5/site-packages/tensorflow/python/pywrap_tensorflow_internal.py", line 28, in <module>
    _pywrap_tensorflow_internal = swig_import_helper()
  File "/home/casperneo/.conda/envs/cc2/lib/python3.5/site-packages/tensorflow/python/pywrap_tensorflow_internal.py", line 24, in swig_import_helper
    _mod = imp.load_module('_pywrap_tensorflow_internal', fp, pathname, description)
  File "/home/casperneo/.conda/envs/cc2/lib/python3.5/imp.py", line 243, in load_module
    return load_dynamic(name, filename, file)
  File "/home/casperneo/.conda/envs/cc2/lib/python3.5/imp.py", line 343, in load_dynamic
    return _load(spec)
ImportError: /lib64/libc.so.6: version `GLIBC_2.17' not found (required by /home/casperneo/.conda/envs/cc2/lib/python3.5/site-packages/tensorflow/python/_pywrap_tensorflow_internal.so)


Failed to load the native TensorFlow runtime.

See https://www.tensorflow.org/install/install_sources#common_installation_problems

for some common reasons and solutions.  Include the entire stack trace
above this error message when asking for help.
Traceback (most recent call last):
  File "/home/casperneo/.conda/envs/cc2/lib/python3.5/site-packages/tensorflow/python/pywrap_tensorflow.py", line 58, in <module>
    from tensorflow.python.pywrap_tensorflow_internal import *
  File "/home/casperneo/.conda/envs/cc2/lib/python3.5/site-packages/tensorflow/python/pywrap_tensorflow_internal.py", line 28, in <module>
    _pywrap_tensorflow_internal = swig_import_helper()
  File "/home/casperneo/.conda/envs/cc2/lib/python3.5/site-packages/tensorflow/python/pywrap_tensorflow_internal.py", line 24, in swig_import_helper
    _mod = imp.load_module('_pywrap_tensorflow_internal', fp, pathname, description)
  File "/home/casperneo/.conda/envs/cc2/lib/python3.5/imp.py", line 243, in load_module
    return load_dynamic(name, filename, file)
  File "/home/casperneo/.conda/envs/cc2/lib/python3.5/imp.py", line 343, in load_dynamic
    return _load(spec)
ImportError: /lib64/libc.so.6: version `GLIBC_2.17' not found (required by /home/casperneo/.conda/envs/cc2/lib/python3.5/site-packages/tensorflow/python/_pywrap_tensorflow_internal.so)

During handling of the above exception, another exception occurred:

Traceback (most recent call last):
  File "reproduction/pipeline/into_record.py", line 1, in <module>
    import tensorflow as tf
  File "/home/casperneo/.conda/envs/cc2/lib/python3.5/site-packages/tensorflow/__init__.py", line 22, in <module>
    from tensorflow.python import pywrap_tensorflow  # pylint: disable=unused-import
  File "/home/casperneo/.conda/envs/cc2/lib/python3.5/site-packages/tensorflow/python/__init__.py", line 49, in <module>
    from tensorflow.python import pywrap_tensorflow
  File "/home/casperneo/.conda/envs/cc2/lib/python3.5/site-packages/tensorflow/python/pywrap_tensorflow.py", line 74, in <module>
    raise ImportError(msg)
ImportError: Traceback (most recent call last):
  File "/home/casperneo/.conda/envs/cc2/lib/python3.5/site-packages/tensorflow/python/pywrap_tensorflow.py", line 58, in <module>
    from tensorflow.python.pywrap_tensorflow_internal import *
  File "/home/casperneo/.conda/envs/cc2/lib/python3.5/site-packages/tensorflow/python/pywrap_tensorflow_internal.py", line 28, in <module>
    _pywrap_tensorflow_internal = swig_import_helper()
  File "/home/casperneo/.conda/envs/cc2/lib/python3.5/site-packages/tensorflow/python/pywrap_tensorflow_internal.py", line 24, in swig_import_helper
    _mod = imp.load_module('_pywrap_tensorflow_internal', fp, pathname, description)
  File "/home/casperneo/.conda/envs/cc2/lib/python3.5/imp.py", line 243, in load_module
    return load_dynamic(name, filename, file)
  File "/home/casperneo/.conda/envs/cc2/lib/python3.5/imp.py", line 343, in load_dynamic
    return _load(spec)
ImportError: /lib64/libc.so.6: version `GLIBC_2.17' not found (required by /home/casperneo/.conda/envs/cc2/lib/python3.5/site-packages/tensorflow/python/_pywrap_tensorflow_internal.so)


Failed to load the native TensorFlow runtime.

See https://www.tensorflow.org/install/install_sources#common_installation_problems

for some common reasons and solutions.  Include the entire stack trace
above this error message when asking for help.
Traceback (most recent call last):
  File "/home/casperneo/.conda/envs/cc2/lib/python3.5/site-packages/tensorflow/python/pywrap_tensorflow.py", line 58, in <module>
    from tensorflow.python.pywrap_tensorflow_internal import *
  File "/home/casperneo/.conda/envs/cc2/lib/python3.5/site-packages/tensorflow/python/pywrap_tensorflow_internal.py", line 28, in <module>
    _pywrap_tensorflow_internal = swig_import_helper()
  File "/home/casperneo/.conda/envs/cc2/lib/python3.5/site-packages/tensorflow/python/pywrap_tensorflow_internal.py", line 24, in swig_import_helper
    _mod = imp.load_module('_pywrap_tensorflow_internal', fp, pathname, description)
  File "/home/casperneo/.conda/envs/cc2/lib/python3.5/imp.py", line 243, in load_module
    return load_dynamic(name, filename, file)
  File "/home/casperneo/.conda/envs/cc2/lib/python3.5/imp.py", line 343, in load_dynamic
    return _load(spec)
ImportError: /lib64/libc.so.6: version `GLIBC_2.17' not found (required by /home/casperneo/.conda/envs/cc2/lib/python3.5/site-packages/tensorflow/python/_pywrap_tensorflow_internal.so)

During handling of the above exception, another exception occurred:

Traceback (most recent call last):
  File "reproduction/pipeline/into_record.py", line 1, in <module>
    import tensorflow as tf
  File "/home/casperneo/.conda/envs/cc2/lib/python3.5/site-packages/tensorflow/__init__.py", line 22, in <module>
    from tensorflow.python import pywrap_tensorflow  # pylint: disable=unused-import
  File "/home/casperneo/.conda/envs/cc2/lib/python3.5/site-packages/tensorflow/python/__init__.py", line 49, in <module>
    from tensorflow.python import pywrap_tensorflow
  File "/home/casperneo/.conda/envs/cc2/lib/python3.5/site-packages/tensorflow/python/pywrap_tensorflow.py", line 74, in <module>
    raise ImportError(msg)
ImportError: Traceback (most recent call last):
  File "/home/casperneo/.conda/envs/cc2/lib/python3.5/site-packages/tensorflow/python/pywrap_tensorflow.py", line 58, in <module>
    from tensorflow.python.pywrap_tensorflow_internal import *
  File "/home/casperneo/.conda/envs/cc2/lib/python3.5/site-packages/tensorflow/python/pywrap_tensorflow_internal.py", line 28, in <module>
    _pywrap_tensorflow_internal = swig_import_helper()
  File "/home/casperneo/.conda/envs/cc2/lib/python3.5/site-packages/tensorflow/python/pywrap_tensorflow_internal.py", line 24, in swig_import_helper
    _mod = imp.load_module('_pywrap_tensorflow_internal', fp, pathname, description)
  File "/home/casperneo/.conda/envs/cc2/lib/python3.5/imp.py", line 243, in load_module
    return load_dynamic(name, filename, file)
  File "/home/casperneo/.conda/envs/cc2/lib/python3.5/imp.py", line 343, in load_dynamic
    return _load(spec)
ImportError: /lib64/libc.so.6: version `GLIBC_2.17' not found (required by /home/casperneo/.conda/envs/cc2/lib/python3.5/site-packages/tensorflow/python/_pywrap_tensorflow_internal.so)


Failed to load the native TensorFlow runtime.

See https://www.tensorflow.org/install/install_sources#common_installation_problems

for some common reasons and solutions.  Include the entire stack trace
above this error message when asking for help.
Traceback (most recent call last):
  File "/home/casperneo/.conda/envs/cc2/lib/python3.5/site-packages/tensorflow/python/pywrap_tensorflow.py", line 58, in <module>
    from tensorflow.python.pywrap_tensorflow_internal import *
  File "/home/casperneo/.conda/envs/cc2/lib/python3.5/site-packages/tensorflow/python/pywrap_tensorflow_internal.py", line 28, in <module>
    _pywrap_tensorflow_internal = swig_import_helper()
  File "/home/casperneo/.conda/envs/cc2/lib/python3.5/site-packages/tensorflow/python/pywrap_tensorflow_internal.py", line 24, in swig_import_helper
    _mod = imp.load_module('_pywrap_tensorflow_internal', fp, pathname, description)
  File "/home/casperneo/.conda/envs/cc2/lib/python3.5/imp.py", line 243, in load_module
    return load_dynamic(name, filename, file)
  File "/home/casperneo/.conda/envs/cc2/lib/python3.5/imp.py", line 343, in load_dynamic
    return _load(spec)
ImportError: /lib64/libc.so.6: version `GLIBC_2.17' not found (required by /home/casperneo/.conda/envs/cc2/lib/python3.5/site-packages/tensorflow/python/_pywrap_tensorflow_internal.so)

During handling of the above exception, another exception occurred:

Traceback (most recent call last):
  File "reproduction/pipeline/into_record.py", line 1, in <module>
    import tensorflow as tf
  File "/home/casperneo/.conda/envs/cc2/lib/python3.5/site-packages/tensorflow/__init__.py", line 22, in <module>
    from tensorflow.python import pywrap_tensorflow  # pylint: disable=unused-import
  File "/home/casperneo/.conda/envs/cc2/lib/python3.5/site-packages/tensorflow/python/__init__.py", line 49, in <module>
    from tensorflow.python import pywrap_tensorflow
  File "/home/casperneo/.conda/envs/cc2/lib/python3.5/site-packages/tensorflow/python/pywrap_tensorflow.py", line 74, in <module>
    raise ImportError(msg)
ImportError: Traceback (most recent call last):
  File "/home/casperneo/.conda/envs/cc2/lib/python3.5/site-packages/tensorflow/python/pywrap_tensorflow.py", line 58, in <module>
    from tensorflow.python.pywrap_tensorflow_internal import *
  File "/home/casperneo/.conda/envs/cc2/lib/python3.5/site-packages/tensorflow/python/pywrap_tensorflow_internal.py", line 28, in <module>
    _pywrap_tensorflow_internal = swig_import_helper()
  File "/home/casperneo/.conda/envs/cc2/lib/python3.5/site-packages/tensorflow/python/pywrap_tensorflow_internal.py", line 24, in swig_import_helper
    _mod = imp.load_module('_pywrap_tensorflow_internal', fp, pathname, description)
  File "/home/casperneo/.conda/envs/cc2/lib/python3.5/imp.py", line 243, in load_module
    return load_dynamic(name, filename, file)
  File "/home/casperneo/.conda/envs/cc2/lib/python3.5/imp.py", line 343, in load_dynamic
    return _load(spec)
ImportError: /lib64/libc.so.6: version `GLIBC_2.17' not found (required by /home/casperneo/.conda/envs/cc2/lib/python3.5/site-packages/tensorflow/python/_pywrap_tensorflow_internal.so)


Failed to load the native TensorFlow runtime.

See https://www.tensorflow.org/install/install_sources#common_installation_problems

for some common reasons and solutions.  Include the entire stack trace
above this error message when asking for help.
-------------------------------------------------------
Primary job  terminated normally, but 1 process returned
a non-zero exit code. Per user-direction, the job has been aborted.
-------------------------------------------------------
--------------------------------------------------------------------------
mpiexec detected that one or more processes exited with non-zero status, thus causing
the job to be terminated. The first process to do so was:

  Process name: [[4252,1],0]
  Exit code:    1
--------------------------------------------------------------------------
