Traceback (most recent call last):
  File "reproduction/pipeline/into_record.py", line 3, in <module>
    import cv2
ImportError: libbz2.so.1.0: cannot open shared object file: No such file or directory
Traceback (most recent call last):
  File "reproduction/pipeline/into_record.py", line 3, in <module>
    import cv2
ImportError: libbz2.so.1.0: cannot open shared object file: No such file or directory
Traceback (most recent call last):
  File "reproduction/pipeline/into_record.py", line 3, in <module>
    import cv2
ImportError: libbz2.so.1.0: cannot open shared object file: No such file or directory
Traceback (most recent call last):
  File "reproduction/pipeline/into_record.py", line 3, in <module>
    import cv2
ImportError: libbz2.so.1.0: cannot open shared object file: No such file or directory
[proxy:0:0@cc054] HYD_pmcd_pmip_control_cmd_cb (pm/pmiserv/pmip_cb.c:909): assert (!closed) failed
[proxy:0:0@cc054] HYDT_dmxu_poll_wait_for_event (tools/demux/demux_poll.c:76): callback returned error status
[proxy:0:0@cc054] main (pm/pmiserv/pmip.c:206): demux engine error waiting for event
[proxy:0:2@cc102] HYD_pmcd_pmip_control_cmd_cb (pm/pmiserv/pmip_cb.c:909): assert (!closed) failed
[proxy:0:2@cc102] HYDT_dmxu_poll_wait_for_event (tools/demux/demux_poll.c:76): callback returned error status
[proxy:0:2@cc102] main (pm/pmiserv/pmip.c:206): demux engine error waiting for event
[proxy:0:3@cc026] HYD_pmcd_pmip_control_cmd_cb (pm/pmiserv/pmip_cb.c:909): assert (!closed) failed
[proxy:0:3@cc026] HYDT_dmxu_poll_wait_for_event (tools/demux/demux_poll.c:76): callback returned error status
[proxy:0:3@cc026] main (pm/pmiserv/pmip.c:206): demux engine error waiting for event
[mpiexec@cc054] HYDT_bscu_wait_for_completion (tools/bootstrap/utils/bscu_wait.c:76): one of the processes terminated badly; aborting
[mpiexec@cc054] HYDT_bsci_wait_for_completion (tools/bootstrap/src/bsci_wait.c:23): launcher returned error waiting for completion
[mpiexec@cc054] HYD_pmci_wait_for_completion (pm/pmiserv/pmiserv_pmci.c:218): launcher returned error waiting for completion
[mpiexec@cc054] main (ui/mpich/mpiexec.c:344): process manager error waiting for completion
Traceback (most recent call last):
  File "reproduction/pipeline/into_record.py", line 8, in <module>
    from osgeo import gdal
ModuleNotFoundError: No module named 'osgeo'
Traceback (most recent call last):
  File "reproduction/pipeline/into_record.py", line 8, in <module>
    from osgeo import gdal
ModuleNotFoundError: No module named 'osgeo'
[proxy:0:0@cc052] HYD_pmcd_pmip_control_cmd_cb (pm/pmiserv/pmip_cb.c:909): assert (!closed) failed
[proxy:0:0@cc052] HYDT_dmxu_poll_wait_for_event (tools/demux/demux_poll.c:76): callback returned error status
[proxy:0:0@cc052] main (pm/pmiserv/pmip.c:206): demux engine error waiting for event
[proxy:0:3@cc023] HYD_pmcd_pmip_control_cmd_cb (pm/pmiserv/pmip_cb.c:909): assert (!closed) failed
[proxy:0:3@cc023] HYDT_dmxu_poll_wait_for_event (tools/demux/demux_poll.c:76): callback returned error status
[proxy:0:3@cc023] main (pm/pmiserv/pmip.c:206): demux engine error waiting for event
[mpiexec@cc052] HYDT_bscu_wait_for_completion (tools/bootstrap/utils/bscu_wait.c:76): one of the processes terminated badly; aborting
[mpiexec@cc052] HYDT_bsci_wait_for_completion (tools/bootstrap/src/bsci_wait.c:23): launcher returned error waiting for completion
[mpiexec@cc052] HYD_pmci_wait_for_completion (pm/pmiserv/pmiserv_pmci.c:218): launcher returned error waiting for completion
[mpiexec@cc052] main (ui/mpich/mpiexec.c:344): process manager error waiting for completion
Traceback (most recent call last):
  File "reproduction/pipeline/into_record.py", line 9, in <module>
    from mpi4py import MPI
ModuleNotFoundError: No module named 'mpi4py'
Traceback (most recent call last):
  File "reproduction/pipeline/into_record.py", line 9, in <module>
    from mpi4py import MPI
ModuleNotFoundError: No module named 'mpi4py'
Traceback (most recent call last):
  File "reproduction/pipeline/into_record.py", line 9, in <module>
    from mpi4py import MPI
ModuleNotFoundError: No module named 'mpi4py'
[proxy:0:0@cc052] HYD_pmcd_pmip_control_cmd_cb (pm/pmiserv/pmip_cb.c:909): assert (!closed) failed
[proxy:0:0@cc052] HYDT_dmxu_poll_wait_for_event (tools/demux/demux_poll.c:76): callback returned error status
[proxy:0:0@cc052] main (pm/pmiserv/pmip.c:206): demux engine error waiting for event
[proxy:0:1@cc102] HYD_pmcd_pmip_control_cmd_cb (pm/pmiserv/pmip_cb.c:909): assert (!closed) failed
[proxy:0:1@cc102] HYDT_dmxu_poll_wait_for_event (tools/demux/demux_poll.c:76): callback returned error status
[proxy:0:1@cc102] main (pm/pmiserv/pmip.c:206): demux engine error waiting for event
[proxy:0:3@cc023] HYD_pmcd_pmip_control_cmd_cb (pm/pmiserv/pmip_cb.c:909): assert (!closed) failed
[proxy:0:3@cc023] HYDT_dmxu_poll_wait_for_event (tools/demux/demux_poll.c:76): callback returned error status
[proxy:0:3@cc023] main (pm/pmiserv/pmip.c:206): demux engine error waiting for event
[mpiexec@cc052] HYDT_bscu_wait_for_completion (tools/bootstrap/utils/bscu_wait.c:76): one of the processes terminated badly; aborting
[mpiexec@cc052] HYDT_bsci_wait_for_completion (tools/bootstrap/src/bsci_wait.c:23): launcher returned error waiting for completion
[mpiexec@cc052] HYD_pmci_wait_for_completion (pm/pmiserv/pmiserv_pmci.c:218): launcher returned error waiting for completion
[mpiexec@cc052] main (ui/mpich/mpiexec.c:344): process manager error waiting for completion
Traceback (most recent call last):
  File "reproduction/pipeline/into_record.py", line 9, in <module>
    from mpi4py import MPI
ImportError: /home/casper/.conda/envs/clouds/lib/python3.6/site-packages/mpi4py/MPI.cpython-36m-x86_64-linux-gnu.so: undefined symbol: MPI_File_iwrite_all
Traceback (most recent call last):
  File "reproduction/pipeline/into_record.py", line 9, in <module>
    from mpi4py import MPI
ImportError: /home/casper/.conda/envs/clouds/lib/python3.6/site-packages/mpi4py/MPI.cpython-36m-x86_64-linux-gnu.so: undefined symbol: MPI_File_iwrite_all
Traceback (most recent call last):
  File "reproduction/pipeline/into_record.py", line 9, in <module>
    from mpi4py import MPI
ImportError: /home/casper/.conda/envs/clouds/lib/python3.6/site-packages/mpi4py/MPI.cpython-36m-x86_64-linux-gnu.so: undefined symbol: MPI_File_iwrite_all
Traceback (most recent call last):
  File "reproduction/pipeline/into_record.py", line 9, in <module>
    from mpi4py import MPI
ImportError: /home/casper/.conda/envs/clouds/lib/python3.6/site-packages/mpi4py/MPI.cpython-36m-x86_64-linux-gnu.so: undefined symbol: MPI_File_iwrite_all
usage: into_record.py [-h] [--shape SHAPE SHAPE] [--resize RESIZE]
                      [--stride STRIDE STRIDE]
                      [--patches_per_record PATCHES_PER_RECORD]
                      source_glob out_dir {mod09_tif,mod02_1km}
into_record.py: error: argument --stride: expected 2 arguments
/gpfs/mira-home/casper/clouds/qs/translate-mod02.sh: line 16: 64: command not found
usage: into_record.py [-h] [--shape SHAPE SHAPE] [--resize RESIZE]
                      [--stride STRIDE STRIDE]
                      [--patches_per_record PATCHES_PER_RECORD]
                      source_glob out_dir {mod09_tif,mod02_1km}
into_record.py: error: argument --stride: expected 2 arguments
/gpfs/mira-home/casper/clouds/cooley/translate-mod02.sh: line 14: 64: command not found
[mpiexec@cc032] set_default_values (ui/mpich/utils.c:1488): no executable specified
[mpiexec@cc032] HYD_uii_mpx_get_parameters (ui/mpich/utils.c:1739): setting default values failed
[mpiexec@cc032] main (ui/mpich/mpiexec.c:149): error parsing parameters
usage: into_record.py [-h] [--shape SHAPE SHAPE] [--resize RESIZE]
                      [--stride STRIDE STRIDE]
                      [--patches_per_record PATCHES_PER_RECORD]
                      source_glob out_dir {mod09_tif,mod02_1km}
into_record.py: error: argument --stride: expected 2 arguments
