/tmp/slurmd/job48444428/slurm_script: line 0: unalias: pine: not found
/tmp/slurmd/job48444428/slurm_script: line 0: unalias: quota: not found
/tmp/slurmd/job48444428/slurm_script: line 0: unalias: chsh: not found
/tmp/slurmd/job48444428/slurm_script: line 0: unalias: grpe: not found
/tmp/slurmd/job48444428/slurm_script: line 0: unalias: alloc: not found
/tmp/slurmd/job48444428/slurm_script: line 0: unalias: vi: not found
/tmp/slurmd/job48444428/slurm_script: line 0: unalias: chfn: not found
Traceback (most recent call last):
  File "/home/casperneo/.local/lib/python3.6/site-packages/tensorflow/python/framework/ops.py", line 1589, in _create_c_op
    c_op = c_api.TF_FinishOperation(op_desc)
tensorflow.python.framework.errors_impl.InvalidArgumentError: Negative dimension size caused by subtracting 3 from 2 for 'discriminator/conv2d_26/Conv2D' (op: 'Conv2D') with input shapes: [?,2,2,512], [3,3,512,1].

During handling of the above exception, another exception occurred:

Traceback (most recent call last):
  File "train2.py", line 252, in <module>
    FLAGS.discriminator, "discriminator", FLAGS.shape, FLAGS.n_layers
  File "train2.py", line 211, in define_model
    return builder(shape, n_layers)
  File "/home/casperneo/clouds/dnn/model.py", line 44, in discriminator
    x = Conv2D(1, 3)(x)
  File "/home/casperneo/.local/lib/python3.6/site-packages/tensorflow/python/keras/engine/base_layer.py", line 703, in __call__
    outputs = self.call(inputs, *args, **kwargs)
  File "/home/casperneo/.local/lib/python3.6/site-packages/tensorflow/python/keras/layers/convolutional.py", line 184, in call
    outputs = self._convolution_op(inputs, self.kernel)
  File "/home/casperneo/.local/lib/python3.6/site-packages/tensorflow/python/ops/nn_ops.py", line 868, in __call__
    return self.conv_op(inp, filter)
  File "/home/casperneo/.local/lib/python3.6/site-packages/tensorflow/python/ops/nn_ops.py", line 520, in __call__
    return self.call(inp, filter)
  File "/home/casperneo/.local/lib/python3.6/site-packages/tensorflow/python/ops/nn_ops.py", line 204, in __call__
    name=self.name)
  File "/home/casperneo/.local/lib/python3.6/site-packages/tensorflow/python/ops/gen_nn_ops.py", line 956, in conv2d
    data_format=data_format, dilations=dilations, name=name)
  File "/home/casperneo/.local/lib/python3.6/site-packages/tensorflow/python/framework/op_def_library.py", line 787, in _apply_op_helper
    op_def=op_def)
  File "/home/casperneo/.local/lib/python3.6/site-packages/tensorflow/python/framework/ops.py", line 3414, in create_op
    op_def=op_def)
  File "/home/casperneo/.local/lib/python3.6/site-packages/tensorflow/python/framework/ops.py", line 1756, in __init__
    control_input_ops)
  File "/home/casperneo/.local/lib/python3.6/site-packages/tensorflow/python/framework/ops.py", line 1592, in _create_c_op
    raise ValueError(str(e))
ValueError: Negative dimension size caused by subtracting 3 from 2 for 'discriminator/conv2d_26/Conv2D' (op: 'Conv2D') with input shapes: [?,2,2,512], [3,3,512,1].
